LookupError at /accounts/profile/
**********************************************************************
  Resource [93mpunkt_tab[0m not found.
  Please use the NLTK Downloader to obtain the resource:

  [31m>>> import nltk
  >>> nltk.download('punkt_tab')
  [0m
  For more information see: https://www.nltk.org/data.html

  Attempted to load [93mtokenizers/punkt_tab/english/[0m

  Searched in:
    - '/home/runner/nltk_data'
    - '/nix/store/qlb1pg370bb647nj4dhc81y2jszvciz7-python3-3.10.16/nltk_data'
    - '/nix/store/qlb1pg370bb647nj4dhc81y2jszvciz7-python3-3.10.16/share/nltk_data'
    - '/nix/store/qlb1pg370bb647nj4dhc81y2jszvciz7-python3-3.10.16/lib/nltk_data'
    - '/usr/share/nltk_data'
    - '/usr/local/share/nltk_data'
    - '/usr/lib/nltk_data'
    - '/usr/local/lib/nltk_data'
**********************************************************************
Request Method:	POST
Request URL:	http://24513667-8886-42bd-ad0b-0fcc66831384-00-3br5nilf1egqd.pike.replit.dev/accounts/profile/
Django Version:	5.0.2
Exception Type:	LookupError
Exception Value:	
**********************************************************************
  Resource [93mpunkt_tab[0m not found.
  Please use the NLTK Downloader to obtain the resource:

  [31m>>> import nltk
  >>> nltk.download('punkt_tab')
  [0m
  For more information see: https://www.nltk.org/data.html

  Attempted to load [93mtokenizers/punkt_tab/english/[0m

  Searched in:
    - '/home/runner/nltk_data'
    - '/nix/store/qlb1pg370bb647nj4dhc81y2jszvciz7-python3-3.10.16/nltk_data'
    - '/nix/store/qlb1pg370bb647nj4dhc81y2jszvciz7-python3-3.10.16/share/nltk_data'
    - '/nix/store/qlb1pg370bb647nj4dhc81y2jszvciz7-python3-3.10.16/lib/nltk_data'
    - '/usr/share/nltk_data'
    - '/usr/local/share/nltk_data'
    - '/usr/lib/nltk_data'
    - '/usr/local/lib/nltk_data'
**********************************************************************
Exception Location:	/home/runner/workspace/.pythonlibs/lib/python3.10/site-packages/nltk/data.py, line 579, in find
Raised during:	accounts.views.profile
Python Executable:	/home/runner/workspace/.pythonlibs/bin/python
Python Version:	3.10.16
Python Path:	
['/home/runner/workspace',
 '/nix/store/lc7qv2ldzrs1aq3hbyzmbgvn0h2w26pl-sitecustomize/lib/python/site-packages',
 '/nix/store/izqbpf8fkd2741sqwdca4a9kfy3ss2dx-python3.10-pip-24.0/lib/python3.10/site-packages',
 '/nix/store/qlb1pg370bb647nj4dhc81y2jszvciz7-python3-3.10.16/lib/python310.zip',
 '/nix/store/qlb1pg370bb647nj4dhc81y2jszvciz7-python3-3.10.16/lib/python3.10',
 '/nix/store/qlb1pg370bb647nj4dhc81y2jszvciz7-python3-3.10.16/lib/python3.10/lib-dynload',
 '/home/runner/workspace/.pythonlibs/lib/python3.10/site-packages',
 '/nix/store/qlb1pg370bb647nj4dhc81y2jszvciz7-python3-3.10.16/lib/python3.10/site-packages',
 '/home/runner/workspace/.pythonlibs/lib/python3.10/site-packages',
 '/nix/store/9ym4wlfl13w339g1jqpgp9llwrqml3jx-python3.10-setuptools-75.1.1/lib/python3.10/site-packages']
Server time:	Thu, 17 Apr 2025 19:20:09 +0000